Workbook

Sheet Sieve AnalysisRTT
A2: Sieve Analysis
C5: % Passing
B6: Sieve Number | C6: Coarse I | D6: Coarse II | E6: Coarse III | F6: Fine I | G6: Fine II
B7: 1.5" | C7: 0 | D7: 1 | E7: 1 | F7: 1 | G7: 0
B8: 1" | C8: 0 | D8: 0.99 | E8: 1 | F8: 1 | G8: 0
B9: 3/4" | C9: 0 | D9: 0.85 | E9: 1 | F9: 1 | G9: 0
B10: 1/2" | C10: 0 | D10: 0.5 | E10: 1 | F10: 1 | G10: 0
B11: 3/8" | C11: 0 | D11: 0.31 | E11: 0.88 | F11: 1 | G11: 0
B12: #4 | C12: 0 | D12: 0.1 | E12: 0.22 | F12: 0.99 | G12: 0
B13: #8 | C13: 0 | D13: 0.05 | E13: 0.05 | F13: 0.84 | G13: 0
B14: #16 | C14: 0 | D14: 0 | E14: 0.04 | F14: 0.66 | G14: 0
B15: #30 | C15: 0 | D15: 0 | E15: 0 | F15: 0.43 | G15: 0
B16: #50 | C16: 0 | D16: 0 | E16: 0 | F16: 0.15 | G16: 0
B17: #100 | C17: 0 | D17: 0 | E17: 0 | F17: 0.03 | G17: 0
B18: #200 | C18: 0 | D18: 0 | E18: 0 | F18: 0.013 | G18: 0
B19: Pan | C19: 0 | D19: 0 | E19: 0 | F19: 0 | G19: 0

Sheet Mix Design
B1: Mixture Design
B4: Batch Weights & Material Properties
B6: Material | C6: Source of Material | E6: Weight (lbs/cy) | F6: Specific Gravity | G6: Volume (ft³)
B7: Coarse I | C7: #4 | E7: 0 | F7: 2.75 | G7: =IF(E7=0, 0, E7/F7/62.4) -> 0
B8: Coarse II | C8: RS57 | E8: 1520 | F8: 2.745 | G8: =IF(E8=0, 0, E8/F8/62.4) -> 8.8739433
B9: Coarse III | C9: RS3/8 | E9: 310 | F9: 2.72 | G9: =IF(E9=0, 0, E9/F9/62.4) -> 1.8264517
B10: Fine I | C10: Dover | E10: 1520 | F10: 2.61 | G10: =IF(E10=0, 0, E10/F10/62.4) -> 9.3329404
B11: Fine II | C11: coleman | E11: =J21 -> 0 | F11: 2.763 | G11: =IF(E11=0, 0, E11/F11/62.4) -> 0
B12: Cement | C12: Lafarge | E12: =K27 -> 413.6 | F12: 3.15 | G12: =IF(E12=0, 0, E12/F12/62.4) -> 2.1041921
B13: Fly Ash | C13: Redrock | E13: =J27 -> 103.4 | F13: 2.5 | G13: =IF(E13=0, 0, E13/F13/62.4) -> 0.66282051
B14: Other Cementitious | G14: =IF(E14=0, 0, E14/F14/62.4) -> 0
B15: Water | E15: =L27 -> 232.65 | F15: 1 | G15: =E15/F15/62.4 -> 3.7283654
B16: Air | C16: 0.02 | G16: =27*C16 -> 0.54
B17: Total | E17: =SUM(E7:E15) -> 4099.65 | F17: lbs/cy | G17: =SUM(G7:G16) -> 27.068713 | H17: cf
E18: =E17/(G17) -> 151.45345 | F18: lbs/cf
B19: Paste Properties
E20: Checks:
B21: Paste Properties | C21: Amounts | E21: Sand Percentages | F21: Amounts | I21: Input
B22: w/cm | C22: =E15/(E12+E13) -> 0.45 | E22: Fine Sand: | F22: =D55 -> 0.30506505 | I22: Sack Content= | J22: 5.5
B23: SCM replacement | C23: =(E13+E14)/(E12+E13+E14) -> 0.2 | E23: Coarse Sand: | F23: =D53 -> 0.32524091 | I23: SCM Replacement= | J23: 0.2
B24: total cementitious | C24: =SUM(E12:E13) -> 517 | D24: lbs | I24: W/cm= | J24: 0.45 | M24: Retained 3/4" | N24: Retained 1/2" | O24: Retained #4
B25: sack content | C25: =C24/94 -> 5.5 | D25: sacks | M25: =D41 -> 0.06201424 | N25: =D42 -> 0.1550356 | O25: =D44 -> 0.15785268
B26: Paste Volume | C26: =SUM(G12:G15)/27*100 -> 24.056956 | D26: % | I26: Total Cementitious | J26: SCM | K26: Cement | L26: Water
I27: =J22*94 -> 517 | J27: =I27*J23 -> 103.4 | K27: =I27-J27 -> 413.6 | L27: =I27*J24 -> 232.65
B28: Admixtures
B30: Admixture Type | C30: Name | E30: Dosage (oz/cwt)
B31: Water reducer
B32: Air entrainer
B33: accelerator
B34: set control
B36: Aggregate Gradation
B38: Sieve Number | C38: Combined % Passing | D38: Combined % Retained | E38: Maximum Boundary | F38: Minimum Boundary
B39: 1.5" | C39: =('Sieve AnalysisRTT'!C7*$G$7/(SUM($G$7:$G$11)))+('Sieve AnalysisRTT'!D7*$G$8/(SUM($G$7:$G$11)))+('Sieve AnalysisRTT'!E7*$G$9/(SUM($G$7:$G$11)))+('Sieve AnalysisRTT'!F7*$G$10/(SUM($G$7:$G$11)))+('Sieve AnalysisRTT'!G7*'Mix Design'!$G$11/(SUM('Mix Design'!$G$7:$G$11))) -> 1 | D39: =IF($C$39=0, 0,1-C39) -> 0 | E39: 0 | F39: 0 | G39: =IF(AND(F39<=D39,D39<=E39),"YES","NO") -> YES
B40: 1" | C40: =('Sieve AnalysisRTT'!C8*$G$7/(SUM($G$7:$G$11)))+('Sieve AnalysisRTT'!D8*$G$8/(SUM($G$7:$G$11)))+('Sieve AnalysisRTT'!E8*$G$9/(SUM($G$7:$G$11)))+('Sieve AnalysisRTT'!F8*$G$10/(SUM($G$7:$G$11)))+('Sieve AnalysisRTT'!G8*'Mix Design'!$G$11/(SUM('Mix Design'!$G$7:$G$11))) -> 0.99557041 | D40: =IF($C$39=0, 0, C39-C40) -> 0.0044295885 | E40: 0.16 | F40: 0 | G40: =IF(AND(F40<=D40,D40<=E40),"YES","NO") -> YES
B41: 3/4" | C41: =('Sieve AnalysisRTT'!C9*$G$7/(SUM($G$7:$G$11)))+('Sieve AnalysisRTT'!D9*$G$8/(SUM($G$7:$G$11)))+('Sieve AnalysisRTT'!E9*$G$9/(SUM($G$7:$G$11)))+('Sieve AnalysisRTT'!F9*$G$10/(SUM($G$7:$G$11)))+('Sieve AnalysisRTT'!G9*'Mix Design'!$G$11/(SUM('Mix Design'!$G$7:$G$11))) -> 0.93355617 | D41: =IF($C$39=0, 0, C40-C41) -> 0.06201424 | E41: 0.2 | F41: 0 | G41: =IF(AND(F41<=D41,D41<=E41),"YES","NO") -> YES
B42: 1/2" | C42: =('Sieve AnalysisRTT'!C10*$G$7/(SUM($G$7:$G$11)))+('Sieve AnalysisRTT'!D10*$G$8/(SUM($G$7:$G$11)))+('Sieve AnalysisRTT'!E10*$G$9/(SUM($G$7:$G$11)))+('Sieve AnalysisRTT'!F10*$G$10/(SUM($G$7:$G$11)))+('Sieve AnalysisRTT'!G10*'Mix Design'!$G$11/(SUM('Mix Design'!$G$7:$G$11))) -> 0.77852057 | D42: =IF($C$39=0, 0, C41-C42) -> 0.1550356 | E42: 0.2 | F42: 0.04 | G42: =IF(AND(F42<=D42,D42<=E42),"YES","NO") -> YES
B43: 3/8" | C43: =('Sieve AnalysisRTT'!C11*$G$7/(SUM($G$7:$G$11)))+('Sieve AnalysisRTT'!D11*$G$8/(SUM($G$7:$G$11)))+('Sieve AnalysisRTT'!E11*$G$9/(SUM($G$7:$G$11)))+('Sieve AnalysisRTT'!F11*$G$10/(SUM($G$7:$G$11)))+('Sieve AnalysisRTT'!G11*'Mix Design'!$G$11/(SUM('Mix Design'!$G$7:$G$11))) -> 0.68341792 | D43: =IF($C$39=0, 0, C42-C43) -> 0.095102657 | E43: 0.2 | F43: 0.04 | G43: =IF(AND(F43<=D43,D43<=E43),"YES","NO") -> YES
B44: #4 | C44: =('Sieve AnalysisRTT'!C12*$G$7/(SUM($G$7:$G$11)))+('Sieve AnalysisRTT'!D12*$G$8/(SUM($G$7:$G$11)))+('Sieve AnalysisRTT'!E12*$G$9/(SUM($G$7:$G$11)))+('Sieve AnalysisRTT'!F12*$G$10/(SUM($G$7:$G$11)))+('Sieve AnalysisRTT'!G12*'Mix Design'!$G$11/(SUM('Mix Design'!$G$7:$G$11))) -> 0.52556524 | D44: =IF($C$39=0, 0, C43-C44) -> 0.15785268 | E44: 0.2 | F44: 0.04 | G44: =IF(AND(F44<=D44,D44<=E44),"YES","NO") -> YES
B45: #8 | C45: =('Sieve AnalysisRTT'!C13*$G$7/(SUM($G$7:$G$11)))+('Sieve AnalysisRTT'!D13*$G$8/(SUM($G$7:$G$11)))+('Sieve AnalysisRTT'!E13*$G$9/(SUM($G$7:$G$11)))+('Sieve AnalysisRTT'!F13*$G$10/(SUM($G$7:$G$11)))+('Sieve AnalysisRTT'!G13*'Mix Design'!$G$11/(SUM('Mix Design'!$G$7:$G$11))) -> 0.41803771 | D45: =IF($C$39=0, 0, C44-C45) -> 0.10752753 | E45: 0.12 | F45: 0 | G45: =IF(AND(F45<=D45,D45<=E45),"YES","NO") -> YES
B46: #16 | C46: =('Sieve AnalysisRTT'!C14*$G$7/(SUM($G$7:$G$11)))+('Sieve AnalysisRTT'!D14*$G$8/(SUM($G$7:$G$11)))+('Sieve AnalysisRTT'!E14*$G$9/(SUM($G$7:$G$11)))+('Sieve AnalysisRTT'!F14*$G$10/(SUM($G$7:$G$11)))+('Sieve AnalysisRTT'!G14*'Mix Design'!$G$11/(SUM('Mix Design'!$G$7:$G$11))) -> 0.31112137 | D46: =IF($C$39=0, 0, C45-C46) -> 0.10691634 | E46: 0.12 | F46: 0 | G46: =IF(AND(F46<=D46,D46<=E46),"YES","NO") -> YES
...

Sheet Sheet5
BX1: Pan | BY1: 1.0214052e-14 | BZ1: 4.4408921e-15 | CA1: 0 | CB1: =AVERAGE(BY1:CA1) -> 4.8849813e-15 | CC1: =STDEV(BY1:CA1) -> 5.1214866e-15
G46: x | H46: y
B47: Workability Box | G47: 0.8 | H47: 0.265
B48: CF | C48: WF | G48: 0.3 | H48: 0.35
B49: 0.68 | C49: 0.32 | D49: 0.68 | E49: 0.32 | G49: =G47 -> 0.8 | H49: =0.38 -> 0.38
B50: 0.68 | C50: 0.36 | D50: 0.52 | E50: 0.34 | G50: 0.3 | H50: 0.465
B51: 0.52 | C51: 0.38 | G51: 0.75 | H51: 0.2735
B52: 0.52 | C52: 0.34 | G52: =G51 -> 0.75 | H52: 0.3885
G53: 0.45 | H53: 0.3245
G54: =G53 -> 0.45 | H54: 0.4395
B58: sieve(in) | C58: sieve(mm) | D58: Sieve(ʍ) | E58: p^.45 | H58: Combined mix proportions | BE58: x | BF58: y
B59: 1.5 | C59: 37.5 | D59: =C59*1000 -> 37500 | E59: =D59^0.45 -> 114.37051 | J59: Mix 2 | BE59: 12 | BF59: 0
B60: 1 | C60: 25 | D60: =C60*1000 -> 25000 | E60: =D60^0.45 -> 95.295634 | H60: Sieve Number | I60: passing% | J60: Retaiened% | K60: cum. Reatained% | BE60: 11 | BF60: 0.18
B61: 0.75 | C61: 19 | D61: =C61*1000 -> 19000 | E61: =D61^0.45 -> 84.224632 | H61: 1.5 | I61: =B$78*'Mix Design'!#REF!+'Mix Design'!#REF!*C$78+D$78*'Mix Design'!#REF! -> #REF! | J61: =1-I61 -> #REF! | K61: =J61 -> #REF! | BE61: 2 | BF61: 0.18
B62: 0.5 | C62: 12.5 | D62: =C62*1000 -> 12500 | E62: =D62^0.45 -> 69.760487 | H62: 1 | I62: =B$78*'Mix Design'!#REF!+'Mix Design'!#REF!*C$78+D$78*'Mix Design'!#REF! -> #REF! | J62: =I61-I62 -> #REF! | K62: =J61+J62 -> #REF! | L62: Max density Line | BE62: 1 | BF62: 0
B63: =3/8 -> 0.375 | C63: 9.5 | D63: =C63*1000 -> 9500 | E63: =D63^0.45 -> 61.656039 | H63: 0.75 | I63: =B$78*'Mix Design'!#REF!+'Mix Design'!#REF!*C$78+D$78*'Mix Design'!#REF! -> #REF! | J63: =I62-I63 -> #REF! | K63: =J62+J63 -> #REF! | L63: =E60 -> 95.295634 | M63: 1 | BE63: 10 | BF63: 0
B64: #4 | C64: 4.75 | D64: =C64*1000 -> 4750 | E64: =D64^0.45 -> 45.134863 | H64: 0.5 | I64: =B$78*'Mix Design'!#REF!+'Mix Design'!#REF!*C$78+D$78*'Mix Design'!#REF! -> #REF! | J64: =I63-I64 -> #REF! | K64: =K63+J64 -> #REF! | L64: 0 | M64: 0 | BE64: 9 | BF64: 0.08
B65: #8 | C65: 2.36 | D65: =C65*1000 -> 2360 | E65: =D65^0.45 -> 32.946585 | H65: 0.375 | I65: =B$78*'Mix Design'!#REF!+'Mix Design'!#REF!*C$78+D$78*'Mix Design'!#REF! -> #REF! | J65: =I64-I65 -> #REF! | K65: =K64+J65 -> #REF! | BE65: 4 | BF65: 0.08
B66: #16 | C66: 1.18 | D66: =C66*1000 -> 1180 | E66: =D66^0.45 -> 24.118312 | H66: #4 | I66: =B$78*'Mix Design'!#REF!+'Mix Design'!#REF!*C$78+D$78*'Mix Design'!#REF! -> #REF! | J66: =I65-I66 -> #REF! | K66: =K65+J66 -> #REF! | L66: high density line | BE66: 3 | BF66: 0
B67: #30 | C67: 0.6 | D67: =C67*1000 -> 600 | E67: =D67^0.45 -> 17.789677 | H67: #8 | I67: =B$78*'Mix Design'!#REF!+'Mix Design'!#REF!*C$78+D$78*'Mix Design'!#REF! -> #REF! | J67: =I66-I67 -> #REF! | K67: =K66+J67 -> #REF! | L67: =L64 -> 0 | M67: =M64 -> 0
B68: #50 | C68: 0.3 | D68: =C68*1000 -> 300 | E68: =D68^0.45 -> 13.022806 | H68: #16 | I68: =B$78*'Mix Design'!C46+'Mix Design'!#REF!*C$78+D$78*'Mix Design'!#REF! -> #REF! | J68: =I67-I68 -> #REF! | K68: =K67+J68 -> #REF! | L68: =E61 -> 84.224632 | M68: =M63 -> 1
B69: #100 | C69: 0.15 | D69: =C69*1000 -> 150 | E69: =D69^0.45 -> 9.5332519 | H69: #30 | I69: =B$78*'Mix Design'!C47+'Mix Design'!#REF!*C$78+D$78*'Mix Design'!#REF! -> #REF! | J69: =I68-I69 -> #REF! | K69: =K68+J69 -> #REF!
B70: #200 | C70: 0.075 | D70: =C70*1000 -> 75 | E70: =D70^0.45 -> 6.9787488 | H70: #50 | I70: =B$78*'Mix Design'!C48+'Mix Design'!#REF!*C$78+D$78*'Mix Design'!#REF! -> #REF! | J70: =I69-I70 -> #REF! | K70: =K69+J70 -> #REF! | L70: low density line | BI70: Trial | BJ70: Aggregate | BK70: Aggregate Proportions | BN70: Unit Weight
H71: #100 | I71: =B$78*'Mix Design'!C49+'Mix Design'!#REF!*C$78+D$78*'Mix Design'!#REF! -> #REF! | J71: =I70-I71 -> #REF! | K71: =K70+J71 -> #REF! | L71: =L67 -> 0 | M71: =M67 -> 0 | BI71: No. | BJ71: type & Size | BK71: G3 | BL71: 3/8" | BM71: SAND | BN71: (b/ft^3) | BO71: SS
H72: #200 | I72: =B$78*'Mix Design'!#REF!+'Mix Design'!#REF!*C$78+D$78*'Mix Design'!#REF! -> #REF! | J72: =I71-I72 -> #REF! | K72: =K71+J72 -> #REF! | L72: =E59 -> 114.37051 | M72: =M68 -> 1 | BI72: 1 | BJ72: Grade 3 & 3/8" | BK72: 0.75 | BL72: 0.25 | BM72: 0 | BN72: 108.02667 | BO72: 7.663598
A73: Mix# | B73: Grade 3 | C73: 3/8" | D73: Sand | E73: total | BI73: 5 | BJ73: Grade 3 & 3/8" | BK73: 0.73529412 | BL73: 0.26470588 | BM73: 0 | BN73: 107.2 | BO73: 7.8076586
A74: 2 | B74: =B81 -> 1763.9585 | C74: =C81 -> 95.270379 | D74: =D81 -> 1420.7975 | E74: =SUM(B74:D74) -> 3280.0264 | BI74: 6 | BJ74: Grade 3 & 3/8" | BK74: 0.65789474 | BL74: 0.34210526 | BM74: 0 | BN74: 106.38667 | BO74: 8.5658725
H75: 1769.101 | I75: 506.79318 | J75: 1085.8139 | AF75: Factor | AG75: % | AJ75: Mix# | AK75: cement | AL75: Fly Ash | BI75: 7 | BJ75: Grade 3 & 3/8" | BK75: 0.80645161 | BL75: 0.19354839 | BM75: 0 | BN75: 105.45333 | BO75: 7.110591
B76: Original Proportions | F76: 0.48979097 | H76: 2132.2672 | I76: 6.3064098 | J76: 1227.0722 | AF76: CF= | AG76: =K65/K67 -> #REF! | AJ76: 2 | AK76: 392 | AL76: 78 | BI76: 8 | BJ76: Grade 3 & 3/8" | BK76: 0.87719298 | BL76: 0.12280702 | BM76: 0 | BN76: 104.04 | BO76: 6.4175998
B77: G3 | C77: 3/8" | D77: Sand | F77: 0.13521913 | I77: 6.216484 | J77: 1255.6498 | AF77: WF= | AG77: =(I67*100+2.5*((AK76+AL76)-564)/94)/100 -> #REF! | BI77: 9 | BJ77: Grade 3 & 3/8" | BK77: 0.7518797 | BL77: 0.2481203 | BM77: 0 | BN77: 108.66667 | BO77: 7.6451842
B78: =B74/E74 -> 0.5377879 | C78: =C74/E74 -> 0.029045614 | D78: =D74/E74 -> 0.43316649 | E78: =SUM(B78:D78) -> 1 | F78: 0.37781724 | BI78: 10 | BJ78: Grade 3 & 3/8" | BK78: 0.72463768 | BL78: 0.27536232 | BM78: 0 | BN78: 109.06667 | BO78: 7.9120504
H79: 1166.6062 | I79: 857.42869 | J79: 1263.9572 | BI79: 11 | BJ79: Grade 3 & 3/8" | BK79: 0.6993007 | BL79: 0.3006993 | BM79: 0 | BN79: 108.96 | BO79: 8.1602546
H80: 1160.3833 | I80: 833.21863 | J80: 1385.5831 | BI80: 12 | BJ80: Grade 3 & 3/8" | BK80: 0.67567568 | BL80: 0.32432432 | BM80: 0 | BN80: 110.45333 | BO80: 8.3916883
B81: 1763.9585 | C81: 95.270379 | D81: 1420.7975 | BI81: 13 | BJ81: Grade 3 & 3/8" | BK81: 0.65359477 | BL81: 0.34640523 | BM81: 0 | BN81: 110.53333 | BO81: 8.6079955
BI82: 14 | BJ82: Grade 3 & 3/8" | BK82: 0.7518797 | BL82: 0.2481203 | BM82: 0 | BN82: 108.58667 | BO82: 7.6451842
BI83: 15 | BJ83: Grade 3 & 3/8" | BK83: 0.72463768 | BL83: 0.27536232 | BM83: 0 | BN83: 112.05333 | BO83: 7.9120504
BI84: 16 | BJ84: Grade 3 & 3/8" | BK84: 0.6993007 | BL84: 0.3006993 | BM84: 0 | BN84: 110.69333 | BO84: 8.1602546
A85: Mix# | B85: Grade 3 | C85: 3/8" | D85: Sand | E85: total | J85: Mix 7 | BI85: 17 | BJ85: Grade 3 & 3/8" | BK85: 0.67567568 | BL85: 0.32432432 | BM85: 0 | BN85: 112.08 | BO85: 8.3916883
A86: 7 | B86: 1503 | C86: 560 | D86: 1271 | E86: =B86+C86+D86 -> 3334 | H86: Sieve Number | I86: passing% | J86: Retaiened% | K86: cum. Reatained% | BI86: 18 | BJ86: Grade 3 & 3/8" | BK86: 0.65359477 | BL86: 0.34640523 | BM86: 0 | BN86: 111.44 | BO86: 8.6079955
H87: 1.5 | I87: =B$90*'Mix Design'!#REF!+'Mix Design'!#REF!*C$90+D$90*'Mix Design'!#REF! -> #REF! | J87: =1-I87 -> #REF! | K87: =J87 -> #REF! | BI87: 20 | BJ87: Grade 3 & 3/8" | BK87: 0.86 | BL87: 0.14 | BM87: 0 | BN87: 106.61333 | BO87: 6.5860244
...

Sheet Sheet3
BQ16: Trial | BR16: Aggregate | BS16: Aggregate Proportions | BV16: Unit Weight
BQ17: No. | BR17: type & Size | BS17: G3 | BT17: 3/8" | BU17: SAND | BV17: (b/ft^3) | BW17: wt | BX17: volume | BY17: α (VP/V) | BZ17: vpoid ratio | CI17: Agg
BQ18: 1 | BR18: Grade 3 & 3/8" | BS18: 0.75 | BT18: 0.25 | BV18: 108.02667 | BW18: 27.006667 | BX18: 0.16332043 | BY18: 0.65328173 | BZ18: =1-BY18 -> 0.34671827 | CF18: CF= | CG18: WF= | CI18: void ratio
BQ19: 2 | BR19: Grade 3 | BS19: 1 | BV19: 100.85333 | BW19: 25.213333 | BX19: 0.15247541 | BY19: 0.60990163 | BZ19: =1-BY19 -> 0.39009837 | CB19: 0.48447479 | CC19: 0.19951553 | CD19: 0.31490861 | CE19: 132.02667 | CF19: 0.55856166 | CG19: 0.26675413 | CH19: 0.79841961 | CI19: =1-CH19 -> 0.20158039
BQ20: 3 | BR20: 3/8" | BT20: 1 | BV20: 101.89333 | BW20: 25.473333 | BX20: 0.15404773 | BY20: 0.61619094 | BZ20: =1-BY20 -> 0.38380906 | CB20: 0.48479506 | CC20: 0.16923755 | CD20: 0.34596739 | CE20: 133.65333 | CF20: 0.57763636 | CG20: 0.29085126 | CH20: 0.80825673 | CI20: =1-CH20 -> 0.19174327
BQ21: 4 | BR21: Sand | BU21: 1 | BV21: 111.76 | BW21: 27.94 | BX21: 0.16896468 | BY21: 0.67585873 | BZ21: =1-BY21 -> 0.32414127 | CB21: 0.45372051 | CC21: 0.1991833 | CD21: 0.34709619 | CE21: 131.49333 | CF21: 0.5434212 | CG21: 0.29428457 | CH21: 0.79519432 | CI21: =1-CH21 -> 0.20480568
BQ22: 5 | BR22: Grade 3 & 3/8" | BS22: 0.73529412 | BT22: 0.26470588 | BV22: 107.2 | BW22: 26.8 | BX22: 0.16207063 | BY22: 0.64828254 | BZ22: =1-BY22 -> 0.35171746 | CB22: 0.45392646 | CC22: 0.16931457 | CD22: 0.37675897 | CE22: 131.09333 | CF22: 0.56253189 | CG22: 0.31721413 | CH22: 0.79277536 | CI22: =1-CH22 -> 0.20722464
BQ23: 6 | BR23: Grade 3 & 3/8" | BS23: 0.65789474 | BT23: 0.34210526 | BV23: 106.38667 | BW23: 26.596667 | BX23: 0.16084099 | BY23: 0.64336397 | BZ23: =1-BY23 -> 0.35663603 | CB23: 0.42390844 | CC23: 0.19923696 | CD23: 0.3768546 | CE23: 130.16 | CF23: 0.52746844 | CG23: 0.31976115 | CH23: 0.81438478 | CI23: =1-CH23 -> 0.18561522
AB24: =#REF! -> #REF! | AD24: Factor | AE24: % | AH24: Mix# | AI24: cement | AJ24: Fly Ash | AL24: 0.61085973 | AM24: 0 | AN24: 0.38914027 | AP24: 133.14667 | AR24: 0.34238319 | BQ24: 7 | BR24: Grade 3 & 3/8" | BS24: 0.80645161 | BT24: 0.19354839 | BV24: 105.45333 | BW24: 26.363333 | BX24: 0.15942993 | BY24: 0.63771972 | BZ24: =1-BY24 -> 0.36228028 | CB24: 0.45330916 | CC24: 0.1387126 | CD24: 0.40797824 | CE24: 132.48 | CF24: 0.58313793 | CG24: 0.34141559 | CH24: 0.8011611 | CI24: =1-CH24 -> 0.1988389
J25: Factor | K25: % | M25: Mix# | N25: cement | O25: Fly Ash | Q25: 0.48447479 | R25: 0.19951553 | S25: 0.31490861 | U25: 132.02667 | AD25: CF= | AE25: 0.75295277 | AH25: 2 | AI25: 470 | AJ25: 0 | BQ25: 8 | BR25: Grade 3 & 3/8" | BS25: 0.87719298 | BT25: 0.12280702 | BV25: 104.04 | BW25: 26.01 | BX25: 0.15729318 | BY25: 0.62917271 | BZ25: =1-BY25 -> 0.37082729 | CB25: 0.42390844 | CC25: 0.16913947 | CD25: 0.4069521 | CE25: 135.62667 | CF25: 0.5468054 | CG25: 0.34304397 | CH25: 0.82019029 | CI25: =1-CH25 -> 0.17980971
J26: CF= | K26: 0.55856166 | N26: 470 | O26: 0 | AD26: WF= | AE26: 0.31386307 | BQ26: 9 | BR26: Grade 3 & 3/8" | BS26: 0.7518797 | BT26: 0.2481203 | BV26: 108.66667 | BW26: 27.166667 | BX26: 0.16428802 | BY26: 0.65715207 | BZ26: =1-BY26 -> 0.34284793 | CB26: 0.42337003 | CC26: 0.138442 | CD26: 0.43818798 | CE26: 134.69333 | CF26: 0.56776762 | CG26: 0.36725178 | CH26: 0.81454604 | CI26: =1-CH26 -> 0.18545396
J27: WF= | K27: 0.26675413 | AY27: pass #8 | AZ27: R#8 | BA27: CF= | BB27: WF= | BC27: R3/8 | BQ27: 10 | BR27: Grade 3 & 3/8" | BS27: 0.72463768 | BT27: 0.27536232 | BV27: 109.06667 | BW27: 27.266667 | BX27: 0.16489276 | BY27: 0.65957104 | BZ27: =1-BY27 -> 0.34042896 | CB27: 0.48447479 | CC27: 0.13895618 | CD27: 0.37656904 | CE27: 136.08 | CF27: 0.59789025 | CG27: 0.31455047 | CH27: 0.82293179 | CI27: =1-CH27 -> 0.17706821
AT28: 134.66667 | AU28: 0.42390844 | AV28: 0.19923696 | AW28: 0.3768546 | AX28: 130.16 | AY28: 0.34720004 | AZ28: =1-AY28 -> 0.65279996 | BA28: 0.52746844 | BB28: 0.31976115 | BC28: =BA28*AZ28 -> 0.34433138 | BQ28: 11 | BR28: Grade 3 & 3/8" | BS28: 0.6993007 | BT28: 0.3006993 | BV28: 108.96 | BW28: 27.24 | BX28: 0.16473149 | BY28: 0.65892598 | BZ28: =1-BY28 -> 0.34107402 | CB28: 0.61085973 | CC28: 0 | CD28: 0.38914027 | CE28: 133.14667 | CF28: 0.75295277 | CG28: 0.31386307 | CH28: 0.8016449 | CI28: =1-CH28 -> 0.1983551
AU29: 0.45372051 | AV29: 0.1991833 | AW29: 0.34709619 | AX29: 131.49333 | AY29: 0.32189527 | AZ29: =1-AY29 -> 0.67810473 | BA29: 0.5434212 | BB29: 0.29428457 | BC29: =BA29*AZ29 -> 0.36849649 | BQ29: 12 | BR29: Grade 3 & 3/8" | BS29: 0.67567568 | BT29: 0.32432432 | BV29: 110.45333 | BW29: 27.613333 | BX29: 0.1669892 | BY29: 0.66795678 | BZ29: =1-BY29 -> 0.33204322 | CB29: 0.59734513 | CC29: 0 | CD29: 0.40265487 | CE29: 133.81333 | CF29: 0.7493881 | CG29: 0.32543109 | CH29: 0.80922432 | CI29: =1-CH29 -> 0.19077568
AU30: 0.42390844 | AV30: 0.16913947 | AW30: 0.4069521 | AX30: 135.62667 | AY30: 0.3704832 | AZ30: =1-AY30 -> 0.6295168 | BA30: 0.5468054 | BB30: 0.34304397 | BC30: =BA30*AZ30 -> 0.34422319 | BQ30: 13 | BR30: Grade 3 & 3/8" | BS30: 0.65359477 | BT30: 0.34640523 | BV30: 110.53333 | BW30: 27.633333 | BX30: 0.16711014 | BY30: 0.66844057 | BZ30: =1-BY30 -> 0.33155943 | CB30: 0.58189655 | CC30: 0 | CD30: 0.41810345 | CE30: 136.66667 | CF30: 0.7451548 | CG30: 0.33865454 | CH30: 0.8264796 | CI30: =1-CH30 -> 0.1735204
E31: pass #8 | F31: R#8 | G31: CF= | H31: WF= | I31: R3/8 | AU31: 0.48447479 | AV31: 0.19951553 | AW31: 0.31490861 | AX31: 132.02667 | AY31: 0.29454643 | AZ31: =1-AY31 -> 0.70545357 | BA31: 0.55856166 | BB31: 0.26675413 | BC31: =BA31*AZ31 -> 0.39403932 | BQ31: 14 | BR31: Grade 3 & 3/8" | BS31: 0.7518797 | BT31: 0.2481203 | BV31: 108.58667 | BW31: 27.146667 | BX31: 0.16416707 | BY31: 0.65666828 | BZ31: =1-BY31 -> 0.34333172 | CB31: 0.56657224 | CC31: 0 | CD31: 0.43342776 | CE31: 135.22667 | CF31: 0.74077834 | CG31: 0.35177162 | CH31: 0.81777133 | CI31: =1-CH31 -> 0.18222867
A32: 0.48447479 | B32: 0.19951553 | C32: 0.31490861 | D32: 132.02667 | E32: 0.29175413 | F32: =1-E32 -> 0.70824587 | G32: 0.55856166 | H32: 0.26675413 | I32: 0.39342187 | AU32: 0.45392646 | AV32: 0.16931457 | AW32: 0.37675897 | AX32: 131.09333 | AY32: 0.34482637 | AZ32: =1-AY32 -> 0.65517363 | BA32: 0.56253189 | BB32: 0.31721413 | BC32: =BA32*AZ32 -> 0.36855606 | BQ32: 15 | BR32: Grade 3 & 3/8" | BS32: 0.72463768 | BT32: 0.27536232 | BV32: 112.05333 | BW32: 28.013333 | BX32: 0.16940816 | BY32: 0.67763264 | BZ32: =1-BY32 -> 0.32236736 | CB32: 0.55248619 | CC32: 0 | CD32: 0.44751381 | CE32: 135.76 | CF32: 0.73659006 | CG32: 0.36382879 | CH32: 0.82099661 | CI32: =1-CH32 -> 0.17900339
A33: 0.48479506 | B33: 0.16923755 | C33: 0.34596739 | D33: 133.65333 | E33: 0.31585126 | F33: =1-E33 -> 0.68414874 | G33: 0.57763636 | H33: 0.29085126 | I33: 0.39357268 | AU33: 0.42337003 | AV33: 0.138442 | AW33: 0.43818798 | AX33: 134.69333 | AY33: 0.39468827 | AZ33: =1-AY33 -> 0.60531173 | BA33: 0.56776762 | BB33: 0.36725178 | BC33: =BA33*AZ33 -> 0.3436764 | BQ33: 16 | BR33: Grade 3 & 3/8" | BS33: 0.6993007 | BT33: 0.3006993 | BV33: 110.69333 | BW33: 27.673333 | BX33: 0.16735204 | BY33: 0.66940816 | BZ33: =1-BY33 -> 0.33059184
A34: 0.45372051 | B34: 0.1991833 | C34: 0.34709619 | D34: 131.49333 | E34: 0.32189527 | F34: =1-E34 -> 0.67810473 | G34: 0.5434212 | H34: 0.29428457 | I34: =G34*F34 -> 0.36849649 | AU34: 0.48479506 | AV34: 0.16923755 | AW34: 0.34596739 | AX34: 133.65333 | AY34: 0.31864145 | AZ34: =1-AY34 -> 0.68135855 | BA34: 0.57763636 | BB34: 0.29085126 | BC34: =BA34*AZ34 -> 0.39357747 | BQ34: 17 | BR34: Grade 3 & 3/8" | BS34: 0.67567568 | BT34: 0.32432432 | BV34: 112.08 | BW34: 28.02 | BX34: 0.16944848 | BY34: 0.6777939 | BZ34: =1-BY34 -> 0.3222061
A35: 0.45392646 | B35: 0.16931457 | C35: 0.37675897 | D35: 131.09333 | E35: 0.34482637 | F35: =1-E35 -> 0.65517363 | G35: 0.56253189 | H35: 0.31721413 | I35: =G35*F35 -> 0.36855606 | AU35: 0.45330916 | AV35: 0.1387126 | AW35: 0.40797824 | AX35: 132.48 | AY35: 0.36902466 | AZ35: =1-AY35 -> 0.63097534 | BA35: 0.58313793 | BB35: 0.34141559 | BC35: =BA35*AZ35 -> 0.36794565 | BQ35: 18 | BR35: Grade 3 & 3/8" | BS35: 0.65359477 | BT35: 0.34640523 | BV35: 111.44 | BW35: 27.86 | BX35: 0.16848089 | BY35: 0.67392356 | BZ35: =1-BY35 -> 0.32607644
A36: 0.42390844 | B36: 0.19923696 | C36: 0.3768546 | D36: 130.16 | E36: 0.34720004 | F36: =1-E36 -> 0.65279996 | G36: 0.52746844 | H36: 0.31976115 | I36: =G36*F36 -> 0.34433138 | AU36: 0.48447479 | AV36: 0.13895618 | AW36: 0.37656904 | AX36: 136.08 | AY36: 0.34233922 | AZ36: =1-AY36 -> 0.65766078 | BA36: 0.59789025 | BB36: 0.31455047 | BC36: =BA36*AZ36 -> 0.39320897 | BQ36: 19 | BR36: Grade 3 | BS36: 1 | BV36: 105.04 | BW36: 26.26 | BX36: 0.15880503 | BY36: 0.63522013 | BZ36: =1-BY36 -> 0.36477987
A37: 0.45330916 | B37: 0.1387126 | C37: 0.40797824 | D37: 132.48 | E37: 0.36902466 | F37: =1-E37 -> 0.63097534 | G37: 0.58313793 | H37: 0.34141559 | I37: =G37*F37 -> 0.36794565 | AU37: 0.55248619 | AV37: 0 | AW37: 0.44751381 | AX37: 135.76 | AY37: 0.39201216 | AZ37: =1-AY37 -> 0.60798784 | BA37: 0.73659006 | BB37: 0.36382879 | BC37: 0.45018264 | BQ37: 20 | BR37: Grade 3 & 3/8" | BS37: 0.86 | BT37: 0.14 | BV37: 106.61333 | BW37: 26.653333 | BX37: 0.16118368 | BY37: 0.64473472 | BZ37: =1-BY37 -> 0.35526528
A38: 0.42390844 | B38: 0.16913947 | C38: 0.4069521 | D38: 135.62667 | E38: 0.3704832 | F38: =1-E38 -> 0.6295168 | G38: 0.5468054 | H38: 0.34304397 | I38: =G38*F38 -> 0.34422319 | AU38: 0.56657224 | AV38: 0 | AW38: 0.43342776 | AX38: 135.22667 | AY38: 0.38003625 | AZ38: =1-AY38 -> 0.61996375 | BA38: 0.74077834 | BB38: 0.35177162 | BC38: 0.46167408 | BQ38: 21 | BR38: Grade 3 & 3/8" | BS38: 0.76 | BT38: 0.24 | BV38: 108 | BW38: 27 | BX38: 0.16328012 | BY38: 0.65312046 | BZ38: =1-BY38 -> 0.34687954
A39: 0.42337003 | B39: 0.138442 | C39: 0.43818798 | D39: 134.69333 | E39: 0.39468827 | F39: =1-E39 -> 0.60531173 | G39: 0.56776762 | H39: 0.36725178 | I39: =G39*F39 -> 0.3436764 | AU39: 0.58189655 | AV39: 0 | AW39: 0.41810345 | AX39: 136.66667 | AY39: 0.36700758 | AZ39: =1-AY39 -> 0.63299242 | BA39: 0.7451548 | BB39: 0.33865454 | BC39: 0.47417588 | BQ39: 22 | BR39: Grade 3 & 3/8" | BS39: 0.67 | BT39: 0.33 | BV39: 110.45333 | BW39: 27.613333 | BX39: 0.1669892 | BY39: 0.66795678 | BZ39: =1-BY39 -> 0.33204322
A40: 0.48447479 | B40: 0.13895618 | C40: 0.37656904 | D40: 136.08 | E40: 0.34233922 | F40: =1-E40 -> 0.65766078 | G40: 0.59789025 | H40: 0.31455047 | I40: =G40*F40 -> 0.39320897 | AU40: 0.59734513 | AV40: 0 | AW40: 0.40265487 | AX40: 133.81333 | AY40: 0.35387325 | AZ40: =1-AY40 -> 0.64612675 | BA40: 0.7493881 | BB40: 0.32543109 | BC40: 0.48677921 | BQ40: 23 | BR40: Grade 3 & 3/8" | BS40: 0.64 | BT40: 0.36 | BV40: 108.93333 | BW40: 27.233333 | BX40: 0.16469118 | BY40: 0.65876472 | BZ40: =1-BY40 -> 0.34123528
A41: 0.61085973 | B41: 0 | C41: 0.38914027 | D41: 133.14667 | E41: 0.34238319 | F41: =1-E41 -> 0.65761681 | G41: 0.75295277 | H41: 0.31386307 | I41: =#REF! -> #REF! | AU41: 0.61085973 | AV41: 0 | AW41: 0.38914027 | AX41: 133.14667 | AY41: 0.34238319 | AZ41: =1-AY41 -> 0.65761681 | BA41: 0.75295277 | BB41: 0.31386307 | BC41: =#REF! -> #REF! | BQ41: 24 | BR41: Grade 3 & 3/8" | BS41: 0.62 | BT41: 0.38 | BV41: 108.32 | BW41: 27.08 | BX41: 0.16376391 | BY41: 0.65505564 | BZ41: =1-BY41 -> 0.34494436
A42: 0.59734513 | B42: 0 | C42: 0.40265487 | D42: 133.81333 | E42: 0.35387325 | F42: =1-E42 -> 0.64612675 | G42: 0.7493881 | H42: 0.32543109 | I42: 0.48677921 | BQ42: 25 | BR42: Grade 3 & 3/8" | BS42: 0.57 | BT42: 0.43 | BV42: 109.6 | BW42: 27.4 | BX42: 0.16569908 | BY42: 0.66279632 | BZ42: =1-BY42 -> 0.33720368
A43: 0.58189655 | B43: 0 | C43: 0.41810345 | D43: 136.66667 | E43: 0.36700758 | F43: =1-E43 -> 0.63299242 | G43: 0.7451548 | H43: 0.33865454 | I43: 0.47417588 | BQ43: 26 | BR43: Grade 3 & 3/8" | BS43: 0.52 | BT43: 0.48 | BV43: 109.36 | BW43: 27.34 | BX43: 0.16533624 | BY43: 0.66134494 | BZ43: =1-BY43 -> 0.33865506
A44: 0.56657224 | B44: 0 | C44: 0.43342776 | D44: 135.22667 | E44: 0.38003625 | F44: =1-E44 -> 0.61996375 | G44: 0.74077834 | H44: 0.35177162 | I44: 0.46167408 | BQ44: 27 | BR44: Grade 3 & 3/8" | BS44: 0.48 | BT44: 0.52 | BV44: 111.68 | BW44: 27.92 | BX44: 0.16884373 | BY44: 0.67537494 | BZ44: =1-BY44 -> 0.32462506
A45: 0.55248619 | B45: 0 | C45: 0.44751381 | D45: 135.76 | E45: 0.39201216 | F45: =1-E45 -> 0.60798784 | G45: 0.73659006 | H45: 0.36382879 | I45: 0.45018264 | BQ45: 28 | BR45: 3/8" | BT45: 1 | BV45: 106 | BW45: 26.5 | BX45: 0.16025641 | BY45: 0.64102564 | BZ45: =1-BY45 -> 0.35897436
BQ46: 29 | BR46: Grade 3, 3/8"/sand | BS46: 0.45392646 | BT46: 0.16931457 | BU46: 0.37675897 | BV46: 131.09333 | BW46: 32.773333 | BX46: 0.19819384 | BY46: 0.79277536 | BZ46: =1-BY46 -> 0.20722464
BQ47: 30 | BR47: Grade 3, 3/8"/sand | BS47: 0.45372051 | BT47: 0.1991833 | BU47: 0.34709619 | BV47: 131.49333 | BW47: 32.873333 | BX47: 0.19879858 | BY47: 0.79519432 | BZ47: =1-BY47 -> 0.20480568
AU48: 0.48447479 | AV48: 0.19951553 | AW48: 0.31490861 | AX48: 132.02667 | AY48: 0.29454643 | AZ48: =1-AY48 -> 0.70545357 | BA48: 0.55856166 | BB48: 0.26675413 | BC48: =BA48*AZ48 -> 0.39403932 | BQ48: 31 | BR48: Grade 3, 3/8"/sand | BS48: 0.45330916 | BT48: 0.1387126 | BU48: 0.40797824 | BV48: 132.48 | BW48: 33.12 | BX48: 0.20029028 | BY48: 0.8011611 | BZ48: =1-BY48 -> 0.1988389
AU49: 0.48479506 | AV49: 0.16923755 | AW49: 0.34596739 | AX49: 133.65333 | AY49: 0.31864145 | AZ49: =1-AY49 -> 0.68135855 | BA49: 0.57763636 | BB49: 0.29085126 | BC49: =BA49*AZ49 -> 0.39357747 | BQ49: 32 | BR49: Grade 3, 3/8"/sand | BS49: 0.48479506 | BT49: 0.16923755 | BU49: 0.34596739 | BV49: 133.65333 | BW49: 33.413333 | BX49: 0.20206418 | BY49: 0.80825673 | BZ49: =1-BY49 -> 0.19174327
AU50: 0.45372051 | AV50: 0.1991833 | AW50: 0.34709619 | AX50: 131.49333 | AY50: 0.32189527 | AZ50: =1-AY50 -> 0.67810473 | BA50: 0.5434212 | BB50: 0.29428457 | BC50: =BA50*AZ50 -> 0.36849649 | BQ50: 33 | BR50: Grade 3, 3/8"/sand | BS50: 0.48447479 | BT50: 0.19951553 | BU50: 0.31490861 | BV50: 132.02667 | BW50: 33.006667 | BX50: 0.1996049 | BY50: 0.79841961 | BZ50: =1-BY50 -> 0.20158039
AU51: 0.61085973 | AV51: 0 | AW51: 0.38914027 | AX51: 133.14667 | AY51: 0.34238319 | AZ51: =1-AY51 -> 0.65761681 | BA51: 0.75295277 | BB51: 0.31386307 | BC51: =#REF! -> #REF! | BQ51: 34 | BR51: Grade 3, 3/8"/sand | BS51: 0.48447479 | BT51: 0.13895618 | BU51: 0.37656904 | BV51: 136.08 | BW51: 34.02 | BX51: 0.20573295 | BY51: 0.82293179 | BZ51: =1-BY51 -> 0.17706821
AB52: =#REF! -> #REF! | AD52: Factor | AE52: % | AH52: Mix# | AI52: cement | AJ52: Fly Ash | AL52: 0.59734513 | AM52: 0 | AN52: 0.40265487 | AP52: 133.81333 | AR52: 0.35387325 | AU52: 0.48447479 | AV52: 0.13895618 | AW52: 0.37656904 | AX52: 136.08 | AY52: 0.34233922 | AZ52: =1-AY52 -> 0.65766078 | BA52: 0.59789025 | BB52: 0.31455047 | BC52: =BA52*AZ52 -> 0.39320897 | BQ52: 35 | BR52: Grade 3, 3/8"/sand | BS52: 0.42390844 | BT52: 0.16913947 | BU52: 0.4069521 | BV52: 135.62667 | BW52: 33.906667 | BX52: 0.20504757 | BY52: 0.82019029 | BZ52: =1-BY52 -> 0.17980971
J53: Factor | K53: % | M53: Mix# | N53: cement | O53: Fly Ash | Q53: 0.48479506 | R53: 0.16923755 | S53: 0.34596739 | U53: 133.65333 | AD53: CF= | AE53: 0.7493881 | AH53: 2 | AI53: 470 | AJ53: 0 | AU53: 0.45392646 | AV53: 0.16931457 | AW53: 0.37675897 | AX53: 131.09333 | AY53: 0.34482637 | AZ53: =1-AY53 -> 0.65517363 | BA53: 0.56253189 | BB53: 0.31721413 | BC53: =BA53*AZ53 -> 0.36855606 | BQ53: 36 | BR53: Grade 3, 3/8"/sand | BS53: 0.42337003 | BT53: 0.138442 | BU53: 0.43818798 | BV53: 134.69333 | BW53: 33.673333 | BX53: 0.20363651 | BY53: 0.81454604 | BZ53: =1-BY53 -> 0.18545396
J54: CF= | K54: 0.57763636 | N54: 470 | O54: 0 | AD54: WF= | AE54: 0.32543109 | AT54: 134.66667 | AU54: 0.42390844 | AV54: 0.19923696 | AW54: 0.3768546 | AX54: 130.16 | AY54: 0.34720004 | AZ54: =1-AY54 -> 0.65279996 | BA54: 0.52746844 | BB54: 0.31976115 | BC54: =BA54*AZ54 -> 0.34433138 | BQ54: 37 | BR54: Grade 3, 3/8"/sand | BS54: 0.42372881 | BT54: 0.19915254 | BU54: 0.37711864 | BV54: 134.66667 | BW54: 33.666667 | BX54: 0.20359619 | BY54: 0.81438478 | BZ54: =1-BY54 -> 0.18561522
J55: WF= | K55: 0.29085126 | AU55: 0.59734513 | AV55: 0 | AW55: 0.40265487 | AX55: 133.81333 | AY55: 0.35387325 | AZ55: =1-AY55 -> 0.64612675 | BA55: 0.7493881 | BB55: 0.32543109 | BC55: 0.48677921 | BQ55: 38 | BR55: Grade 3/sand | BS55: 0.59734513 | BU55: 0.40265487 | BV55: 133.81333 | BW55: 33.453333 | BX55: 0.20230608 | BY55: 0.80922432 | BZ55: =1-BY55 -> 0.19077568
...

Sheet Sheet4
D3: The Toufar and modified Toufar model
D4: Toufar et al. (1976) described a model to calculate the packing of binary mixtures for | AF4: LPDM Linear Packing Density Model De Larrard | AN4: (3 Aggregate Blends) | BC4: (2 Aggregate Blends)
D5: diameter ratios 0.22 < d1/d2 < 1.0. The concept of the model is that for diameter ratios > | AJ5: ∑
D6: 0.22 the smaller particles with diameter d1 will actually be too large to be situated within | AG6: n | AN6: equation of wall & loseness effects
D7: the interstices between the larger particles with diameter d2. Therefore, the packing | AG7: αt Min= | AH7: αi/(1-(1-αi) | AK7: ) | AN7: f(z) = 0.7(1- z) + 0.3(1- z)^12 | AQ7: loseness equation
D8: density should depend on the diameter ratio of the two particle classes, as expressed by | AG8: i=1 | AN8: • g(z) = (1 - z) ^1.3 | AQ8: wall effect equation
D9: the factor kd . Furthermore, Toufar et al. considered the statistical probability of the
D10: number of interstices between the coarser particles that are free from smaller particles. It
D11: was assumed that each of the fine particles is placed between exactly four of the coarse | AE11: g | AF11: f | AG11: Agg | AH11: d(mm) | AI11: i | AJ11: a | AL11: r | AM11: j | AN11: z for f(z) | AO11: z for g(z) | AY11: g | AZ11: f | BA11: Agg | BB11: d(mm) | BC11: i | BD11: a | BF11: r | BG11: j | BH11: z for f(z) | BI11: z for g(z)
D12: particles, which led to the factor ks . The total packing density is described by Equations | AE12: =(1-AO12)^1.3 -> 0.68876865 | AF12: =0.7*(1-AN12)+0.3*(1-AN12)^12 -> 0.67413529 | AG12: #57 | AH12: 38.1 | AI12: 1 | AJ12: 0.6 | AL12: 0.4 | AM12: 1 | AN12: =AH14/AH13 -> 0.12421053 | AO12: =AH13/AH12 -> 0.24934383 | AY12: =(1-BI12)^1.3 -> 0.95992595 | AZ12: =0.7*(1-BH12)+0.3*(1-BH12)^12 -> 0.8839859 | BA12: #57 | BB12: 38.1 | BC12: 1 | BD12: 0.6 | BF12: 0.4 | BG12: 1 | BH12: =BB13/BB12 -> 0.030971129 | BI12: =BB13/BB12 -> 0.030971129
D13: 3.8‐3.11 (Goltermann, et al., 1997). | AG13: 3/8" | AH13: 9.5 | AI13: 2 | AJ13: 0.62 | AL13: 0.15 | AM13: 2 | BA13: SAND | BB13: 1.18 | BC13: 2 | BD13: 0.62 | BF13: 0.6 | BG13: 2
AG14: sand | AH14: 1.18 | AI14: 3 | AJ14: 0.65 | AL14: 0.45 | AM14: 3
D15: αt=1/((r1/α1+r2/α2-r2(1/α2-1)kd ks) | AL15: =SUM(AL12:AL14) -> 1 | BF15: =SUM(BF12:BF14) -> 1
AI16: =AJ12/(1-(1-AJ12+AE12*AJ12*(1-1/AJ13))*AL13-(1-AF12*AJ12/AJ13)*AL13) -> 0.64805194 | AL16: (value with wall and loseness effect) | AQ16: =AJ12/(1-(1-AJ12+AJ12*(1-1/AJ13))*AL13-(1-AJ12/AJ13)*AL13) -> 0.60586319 | AT16: (value without wall and loseness effect) | BC16: =BD12/(1-(1-BD12+AY12*BD12*(1-1/BD13))*BF13-(1-AZ12*BD12/BD13)*BF13) -> 0.67790088 | BF16: (value with wall and loseness effect) | BK16: =BD12/(1-(1-BD12+BD12*(1-1/BD13))*BF13-(1-BD12/BD13)*BF13) -> 0.62416107 | BN16: (value without wall and loseness effect)
D17: kd=(d2-d1)/(d1+d2)
D19: ks=1-((1+4x)/(1+x^4)) | I19: modefied ks=0.3881 x/0.4753 | M19: for x ˂ 0.4753 | S19: αi packing density of dominant size class i [‐] | AE19: g | AF19: f | AG19: Agg | AH19: d(mm) | AI19: i | AJ19: a | AL19: r | AM19: j | AN19: z for f(z) | AO19: z for g(z) | AY19: g | AZ19: f | BA19: Agg | BB19: d(mm) | BC19: i | BD19: a | BF19: r | BG19: j | BH19: z for f(z) | BI19: z for g(z)
J20: ks=1-((1+4x)/(1+x^4)) | M20: for x ≥ 0.4753 | S20: αj packing density of size class j [‐] | AE20: =AE12 -> 0.68876865 | AF20: =AF12 -> 0.67413529 | AG20: =AG13 -> 3/8" | AH20: =AH13 -> 9.5 | AI20: =AI13 -> 2 | AJ20: =AJ13 -> 0.62 | AL20: =AL13 -> 0.15 | AM20: =AM13 -> 2 | AN20: =AN12 -> 0.12421053 | AO20: =AO12 -> 0.24934383 | AY20: =(1-BI20)^1.3 -> 0.95992595 | AZ20: =0.7*(1-BH20)+0.3*(1-BH20)^12 -> 0.8839859 | BA20: =BA13 -> SAND | BB20: 38.1 | BC20: 1 | BD20: =BD13 -> 0.62 | BF20: =BF13 -> 0.6 | BG20: 1 | BH20: =BB21/BB20 -> 0.030971129 | BI20: =BB21/BB20 -> 0.030971129
D21: x=r1 α2/(r2 α1 (1- α2)) | S21: αij assisting variable for packing density in the Toufar model [‐] | AG21: =AG14 -> sand | AH21: =AH14 -> 1.18 | AI21: =AI14 -> 3 | AJ21: =AJ14 -> 0.65 | AL21: =AL14 -> 0.45 | AM21: =AM14 -> 3 | BA21: =BA12 -> #57 | BB21: 1.18 | BC21: 2 | BD21: =BD12 -> 0.6 | BF21: =BF12 -> 0.4 | BG21: 2
S22: αt calculated packing density of a mixture [‐]t calculated packing density of a mixture [‐] | AG22: =AG12 -> #57 | AH22: =AH12 -> 38.1 | AI22: =AI12 -> 1 | AJ22: =AJ12 -> 0.6 | AL22: =AL12 -> 0.4 | AM22: =AM12 -> 1
I23: ri-j=rirj/(1-ri) | S23: ϕi partial volume: the volume occupied by size class i in a unit volume [‐] | AL23: =SUM(AL20:AL22) -> 1 | BF23: =SUM(BF20:BF22) -> 1
S24: ϕj partial volume: the volume occupied by size class j in a unit volume [‐] | AI24: =AJ20/(1-(1-AJ20+AE20*AJ20*(1-1/AJ21))*AL21-(1-AF20*AJ20/AJ21)*AL21) -> 0.80328169 | AQ24: =AJ20/(1-(1-AJ20+AJ20*(1-1/AJ21))*AL21-(1-AJ20/AJ21)*AL21) -> 0.64686998 | AT24: (value without wall and loseness effect) | BC24: =BD20/(1-(1-BD20+AY20*BD20*(1-1/BD21))*BF21-(1-AZ20*BD20/BD21)*BF21) -> 0.63780195 | BF24: (value with wall and loseness effect) | BK24: =BD20/(1-(1-BD20+BD20*(1-1/BD21))*BF21-(1-BD20/BD21)*BF21) -> 0.6038961 | BN24: (value without wall and loseness effect)
I25: rij = ri- j + rj-i | S25: d particle diameter [m]
S26: di diameter of dominant size class i [m]
F27: ri | G27: rj | L27: p% by vol | M27: d(mm) | N27: α (VP/V) | O27: agg | S27: dj diameter of particle classj ( j=1 for the largest diameter in the Furnas | AE27: g | AF27: f | AG27: Agg | AH27: d(mm) | AI27: i | AJ27: a | AL27: r | AM27: j | AN27: z for f(z) | AO27: z for g(z) | AY27: Packing Dinsity according to De Larrard= | BC27: =MIN(BC24,BC16) -> 0.63780195 | BK27: =MIN(BK24,BK16) -> 0.6038961 | BN27: (value without wall and loseness effect)
F28: =L28 -> 0.45 | G28: =L29 -> 0.15 | L28: 0.45 | M28: 25 | N28: 0.60990163 | O28: G3 | S28: model, LPDM, CPM, Linear‐Mixture Packing Model and CIPM, for the | AE28: =(1-AO28)^1.3 -> 0.68876865 | AF28: =AF20 -> 0.67413529 | AG28: =AG21 -> sand | AH28: =AH21 -> 1.18 | AI28: =AI21 -> 3 | AJ28: =AJ21 -> 0.65 | AL28: =AL21 -> 0.45 | AM28: =AM21 -> 3 | AN28: =AN20 -> 0.12421053 | AO28: =AO20 -> 0.24934383
F29: =L29 -> 0.15 | G29: =L30 -> 0.4 | L29: 0.15 | M29: 9.5 | N29: 0.61619094 | O29: 3/8" | S29: smallest diameter in the Toufar model and the Dewar model) [m] | AG29: =AG22 -> #57 | AH29: =AH22 -> 38.1 | AI29: =AI22 -> 1 | AJ29: =AJ22 -> 0.6 | AL29: =AL22 -> 0.4 | AM29: =AM22 -> 1
F30: =L30 -> 0.4 | G30: =L28 -> 0.45 | L30: 0.4 | M30: 1.18 | N30: 0.67585873 | O30: SAND | S30: kd diameter ratio of two size classes in the Toufar model [‐] | AG30: =AG20 -> 3/8" | AH30: =AH20 -> 9.5 | AI30: =AI20 -> 2 | AJ30: =AJ20 -> 0.62 | AL30: =AL20 -> 0.15 | AM30: =AM20 -> 2
F31: =SUM(F28:F30) -> 1 | G31: =SUM(G28:G30) -> 1 | L31: =SUM(L28:L30) -> 1 | S31: ks factor in the Toufar model, section 3.3 [‐] | AL31: =SUM(AL28:AL30) -> 1
S32: n number of size classes in a mixture | AI32: =AJ28/(1-(1-AJ28+AE28*AJ28*(1-1/AJ29))*AL29-(1-AF28*AJ28/AJ29)*AL29) -> 0.74583036 | AQ32: =AJ28/(1-(1-AJ28+AJ28*(1-1/AJ29))*AL29-(1-AJ28/AJ29)*AL29) -> 0.609375 | AT32: (value without wall and loseness effect) | AZ32: Refrences:
F33: ri-j | G33: rj-i | H33: rij | I33: kij | J33: x | K33: ks ij | S33: ri volume fraction of size class i , by definition | X33: ri=ϕi/ | Z33: and
F34: =F28*G28/(1-F28) -> 0.12272727 | G34: =G28*F28/(1-G28) -> 0.079411765 | H34: =F34+G34 -> 0.20213904 | I34: =(M28-M29)/(M28+M29) -> 0.44927536 | J34: =G28/F28*N28/(N29*(1-N28)) -> 0.8457638 | S34: rij assisting variable Toufar model [‐] | AZ34: 1-F. de Larrard and T. Sedran. September 23, 1993.( OPTIMIZATION OF ULTRA-HIGH-PERFORNCE CONCRETE BY THE USE OF A PACKING MODEL)
F35: =F29*G29/(1-F29) -> 0.070588235 | G35: =G29*F29/(1-G29) -> 0.1 | H35: =F35+G35 -> 0.17058824 | I35: =(M29-M30)/(M29+M30) -> 0.77902622 | J35: =G29/F29*N29/(N30*(1-N29)) -> 6.3345079 | S35: ri- j assisting variable Toufar model [‐] | AZ35: 2-Sonja A.A.M. Fennis, Joost C. Walraven, Joop A. den Uijl.Delft University of Technology, the Netherlands.(The use of particle packing models to | BN35: design ecological concrete)
F36: =F30*G30/(1-F30) -> 0.3 | G36: =G30*F30/(1-G30) -> 0.32727273 | H36: =F36+G36 -> 0.62727273 | I36: =(M28-M30)/(M28+M30) -> 0.90985485 | S36: rj volume fraction of size class j [‐] | AE36: Packing Dinsity according to De Larrard= | AI36: =MIN(AI16,AI24,AI32) -> 0.64805194 | AL36: (value with wall and loseness effect) | AQ36: =MIN(AQ16,AQ24,AQ32) -> 0.60586319 | AT36: (value without wall and loseness effect) | AZ36: 3-Sebastiana Antonia Adriana Maria FENNIS‐HUIJBEN.17 januari 2011. (Design of Ecological Concrete by Particle Packing Optimization)
G37: sum= | H37: =SUM(H34:H36) -> 1 | S37: rj-i assisting variable Toufar model [‐]
S38: x assisting variable in the Toufar model [‐]
AB40: sieve # | AC40: sieve(in)
AC41: 1.5
AB42: 1" | AC42: 1
F43: ks | G43: (1+x)^4 | H43: 1+4x | I43: x | J43: r1/r2 | K43: kd | L43: p% by vol | M43: p% by vol | N43: d(mm) | O43: α (VP/V) | P43: agg | AB43: 3/4" | AC43: 0.75 | AD43: 19
F44: =1-(H44/G44) -> 0.73110634 | G44: =(1+I44)^4 -> 20.494125 | H44: =1+4*I44 -> 5.5107403 | I44: =L45*O44/(L44*O45*(1-O44)) -> 1.1276851 | J44: =L44/L45 -> 2.25 | K44: =(N44-N45)/(N44+N45) -> 0.44927536 | L44: =M44/(M44+M45) -> 0.69230769 | M44: 0.45 | N44: 25 | O44: 0.60990163 | P44: G3 | AB44: 1/2" | AC44: 0.5 | AD44: 12.5
...
